var
returnCount
=
0
;
function
CatchError
(
)
{
}
var
thrownError
=
new
CatchError
(
)
;
var
uncaughtError
=
new
Error
(
"
Don
'
t
catch
me
"
)
;
const
obj
=
{
[
Symbol
.
iterator
]
(
)
{
return
{
next
(
)
{
return
{
value
:
1
done
:
false
}
;
}
throw
(
)
{
const
p
=
Promise
.
resolve
(
'
FAIL
'
)
;
Object
.
defineProperty
(
p
'
constructor
'
{
get
(
)
{
throw
thrownError
;
}
}
)
;
return
{
value
:
p
done
:
false
}
;
}
return
(
)
{
returnCount
+
=
1
;
return
{
value
:
undefined
done
:
true
}
;
}
}
;
}
}
;
async
function
*
asyncg
(
)
{
return
yield
*
obj
;
}
let
iter
=
asyncg
(
)
;
asyncTest
(
async
function
(
)
{
await
assert
.
throwsAsync
(
CatchError
async
(
)
=
>
{
await
iter
.
next
(
)
;
return
iter
.
throw
(
uncaughtError
)
;
}
"
Promise
should
be
rejected
"
)
;
assert
.
sameValue
(
returnCount
1
'
iterator
closed
properly
'
)
;
const
result
=
await
iter
.
next
(
)
;
assert
(
result
.
done
"
the
iterator
is
completed
"
)
;
assert
.
sameValue
(
result
.
value
undefined
"
value
is
undefined
"
)
;
}
)
