var
first
=
0
;
var
second
=
0
;
var
iter
=
function
*
(
)
{
first
+
=
1
;
throw
new
Test262Error
(
)
;
second
+
=
1
;
}
(
)
;
async
function
fn
(
)
{
for
await
(
const
[
.
.
.
x
]
of
[
iter
]
)
{
return
;
}
}
fn
(
)
.
then
(
_
=
>
{
throw
new
Test262Error
(
"
Expected
async
function
to
reject
but
resolved
.
"
)
;
}
(
{
constructor
}
)
=
>
assert
.
sameValue
(
constructor
Test262Error
)
)
.
then
(
DONE
DONE
)
;
iter
.
next
(
)
;
assert
.
sameValue
(
first
1
)
;
assert
.
sameValue
(
second
0
'
Iterator
is
closed
following
abrupt
completion
.
'
)
;
