var
returnCount
=
0
;
function
CatchError
(
)
{
}
var
thrownError
=
new
CatchError
(
)
;
const
obj
=
{
[
Symbol
.
iterator
]
(
)
{
return
{
next
(
)
{
const
p
=
Promise
.
resolve
(
'
FAIL
'
)
;
Object
.
defineProperty
(
p
'
constructor
'
{
get
(
)
{
throw
thrownError
;
}
}
)
;
return
{
value
:
p
done
:
false
}
;
}
return
(
)
{
returnCount
+
=
1
;
}
}
;
}
}
;
async
function
*
iter
(
)
{
yield
*
obj
;
}
asyncTest
(
async
function
(
)
{
await
assert
.
throwsAsync
(
CatchError
async
(
)
=
>
iter
(
)
.
next
(
)
"
Promise
should
be
rejected
"
)
;
assert
.
sameValue
(
returnCount
1
'
iterator
closed
properly
'
)
;
}
)
